Workbook

Sheet Sales Data
A1: Product | B1: Sales | C1: Expenses | D1: Profit | E1: Region | F1: Quarter | H1: Quarterly Metrics | M1: Quarter | N1: North | O1: South | P1: East | Q1: West
A2: Laptop | B2: 62743.44 | C2: 48227.52 | D2: =B2-C2 -> 14515.92 | E2: North | F2: Q1 | H2: Quarter | I2: Average Sales | J2: Total Expenses | K2: Maximum Profit | M2: Q1 | N2: =SUMIFS($B$2:$B$129,$F$2:$F$129,$M2,$E$2:$E$129,N$1) -> 178772.34 | O2: =SUMIFS($B$2:$B$129,$F$2:$F$129,$M2,$E$2:$E$129,O$1) -> 167559.26 | P2: =SUMIFS($B$2:$B$129,$F$2:$F$129,$M2,$E$2:$E$129,P$1) -> 171984.49 | Q2: =SUMIFS($B$2:$B$129,$F$2:$F$129,$M2,$E$2:$E$129,Q$1) -> 168962.7
A3: Smartphone | B3: 44174.02 | C3: 31813.82 | D3: =B3-C3 -> 12360.2 | E3: North | F3: Q1 | H3: Q1 | I3: =AVERAGEIF($F$2:$F$129,H3,$B$2:$B$129) -> 21477.462 | J3: =SUMIFS($C$2:$C$129,$F$2:$F$129,H3) -> 493192.65 | K3: =MAXIFS($D$2:$D$129,$F$2:$F$129,H3) -> #NAME? | M3: Q2 | N3: =SUMIFS($B$2:$B$129,$F$2:$F$129,$M3,$E$2:$E$129,N$1) -> 196812.25 | O3: =SUMIFS($B$2:$B$129,$F$2:$F$129,$M3,$E$2:$E$129,O$1) -> 189970.68 | P3: =SUMIFS($B$2:$B$129,$F$2:$F$129,$M3,$E$2:$E$129,P$1) -> 191941.91 | Q3: =SUMIFS($B$2:$B$129,$F$2:$F$129,$M3,$E$2:$E$129,Q$1) -> 199409.58
A4: Headphones | B4: 5403.29 | C4: 4281.06 | D4: =B4-C4 -> 1122.23 | E4: North | F4: Q1 | H4: Q2 | I4: =AVERAGEIF($F$2:$F$129,H4,$B$2:$B$129) -> 24316.701 | J4: =SUMIFS($C$2:$C$129,$F$2:$F$129,H4) -> 568519.79 | K4: =MAXIFS($D$2:$D$129,$F$2:$F$129,H4) -> #NAME? | M4: Q3 | N4: =SUMIFS($B$2:$B$129,$F$2:$F$129,$M4,$E$2:$E$129,N$1) -> 223007.53 | O4: =SUMIFS($B$2:$B$129,$F$2:$F$129,$M4,$E$2:$E$129,O$1) -> 171876.91 | P4: =SUMIFS($B$2:$B$129,$F$2:$F$129,$M4,$E$2:$E$129,P$1) -> 197248.68 | Q4: =SUMIFS($B$2:$B$129,$F$2:$F$129,$M4,$E$2:$E$129,Q$1) -> 219902.77
A5: Monitor | B5: 20569.05 | C5: 14971.49 | D5: =B5-C5 -> 5597.56 | E5: North | F5: Q1 | H5: Q3 | I5: =AVERAGEIF($F$2:$F$129,H5,$B$2:$B$129) -> 25376.122 | J5: =SUMIFS($C$2:$C$129,$F$2:$F$129,H5) -> 559833.39 | K5: =MAXIFS($D$2:$D$129,$F$2:$F$129,H5) -> #NAME? | M5: Q4 | N5: =SUMIFS($B$2:$B$129,$F$2:$F$129,$M5,$E$2:$E$129,N$1) -> 232321.69 | O5: =SUMIFS($B$2:$B$129,$F$2:$F$129,$M5,$E$2:$E$129,O$1) -> 228193.73 | P5: =SUMIFS($B$2:$B$129,$F$2:$F$129,$M5,$E$2:$E$129,P$1) -> 203115.31 | Q5: =SUMIFS($B$2:$B$129,$F$2:$F$129,$M5,$E$2:$E$129,Q$1) -> 269768.8
A6: Keyboard | B6: 2458.49 | C6: 1633.16 | D6: =B6-C6 -> 825.33 | E6: North | F6: Q1 | H6: Q4 | I6: =AVERAGEIF($F$2:$F$129,H6,$B$2:$B$129) -> 29168.735 | J6: =SUMIFS($C$2:$C$129,$F$2:$F$129,H6) -> 683374.09 | K6: =MAXIFS($D$2:$D$129,$F$2:$F$129,H6) -> #NAME?
A7: Mouse | B7: 863.13 | C7: 600.17 | D7: =B7-C7 -> 262.96 | E7: North | F7: Q1
A8: Tablet | B8: 26666.67 | C8: 16691.49 | D8: =B8-C8 -> 9975.18 | E8: North | F8: Q1
A9: Printer | B9: 15894.25 | C9: 10544.53 | D9: =B9-C9 -> 5349.72 | E9: North | F9: Q1 | H9: Quarterly Trends by Region
A10: Laptop | B10: 63004 | C10: 39045.92 | D10: =B10-C10 -> 23958.08 | E10: South | F10: Q1 | H10: Quarter | I10: Region | J10: Sales | K10: Profit
A11: Smartphone | B11: 50180.17 | C11: 39135.42 | D11: =B11-C11 -> 11044.75 | E11: South | F11: Q1 | H11: Q1 | I11: North | J11: =SUMIFS($B$2:$B$129,$F$2:$F$129,H11,$E$2:$E$129,I11) -> 178772.34 | K11: =SUMIFS($D$2:$D$129,$F$2:$F$129,H11,$E$2:$E$129,I11) -> 50009.1
A12: Headphones | B12: 7363 | C12: 5534.43 | D12: =B12-C12 -> 1828.57 | E12: South | F12: Q1 | H12: Q1 | I12: South | J12: =SUMIFS($B$2:$B$129,$F$2:$F$129,H12,$E$2:$E$129,I12) -> 167559.26 | K12: =SUMIFS($D$2:$D$129,$F$2:$F$129,H12,$E$2:$E$129,I12) -> 48014.48
A13: Monitor | B13: 12730.31 | C13: 8728.58 | D13: =B13-C13 -> 4001.73 | E13: South | F13: Q1 | H13: Q1 | I13: East | J13: =SUMIFS($B$2:$B$129,$F$2:$F$129,H13,$E$2:$E$129,I13) -> 171984.49 | K13: =SUMIFS($D$2:$D$129,$F$2:$F$129,H13,$E$2:$E$129,I13) -> 46040.26
A14: Keyboard | B14: 2354.4 | C14: 1498.9 | D14: =B14-C14 -> 855.5 | E14: South | F14: Q1 | H14: Q1 | I14: West | J14: =SUMIFS($B$2:$B$129,$F$2:$F$129,H14,$E$2:$E$129,I14) -> 168962.7 | K14: =SUMIFS($D$2:$D$129,$F$2:$F$129,H14,$E$2:$E$129,I14) -> 50022.3
A15: Mouse | B15: 1406.03 | C15: 976.83 | D15: =B15-C15 -> 429.2 | E15: South | F15: Q1 | H15: Q2 | I15: North | J15: =SUMIFS($B$2:$B$129,$F$2:$F$129,H15,$E$2:$E$129,I15) -> 196812.25 | K15: =SUMIFS($D$2:$D$129,$F$2:$F$129,H15,$E$2:$E$129,I15) -> 51658.6
A16: Tablet | B16: 19976.72 | C16: 15941.97 | D16: =B16-C16 -> 4034.75 | E16: South | F16: Q1 | H16: Q2 | I16: South | J16: =SUMIFS($B$2:$B$129,$F$2:$F$129,H16,$E$2:$E$129,I16) -> 189970.68 | K16: =SUMIFS($D$2:$D$129,$F$2:$F$129,H16,$E$2:$E$129,I16) -> 47124.18
A17: Printer | B17: 10544.63 | C17: 8682.73 | D17: =B17-C17 -> 1861.9 | E17: South | F17: Q1 | H17: Q2 | I17: East | J17: =SUMIFS($B$2:$B$129,$F$2:$F$129,H17,$E$2:$E$129,I17) -> 191941.91 | K17: =SUMIFS($D$2:$D$129,$F$2:$F$129,H17,$E$2:$E$129,I17) -> 58962
A18: Laptop | B18: 68835.88 | C18: 50729.34 | D18: =B18-C18 -> 18106.54 | E18: East | F18: Q1 | H18: Q2 | I18: West | J18: =SUMIFS($B$2:$B$129,$F$2:$F$129,H18,$E$2:$E$129,I18) -> 199409.58 | K18: =SUMIFS($D$2:$D$129,$F$2:$F$129,H18,$E$2:$E$129,I18) -> 51869.85
A19: Smartphone | B19: 34817.06 | C19: 25119.88 | D19: =B19-C19 -> 9697.18 | E19: East | F19: Q1 | H19: Q3 | I19: North | J19: =SUMIFS($B$2:$B$129,$F$2:$F$129,H19,$E$2:$E$129,I19) -> 223007.53 | K19: =SUMIFS($D$2:$D$129,$F$2:$F$129,H19,$E$2:$E$129,I19) -> 69564.59
A20: Headphones | B20: 4895.75 | C20: 3028.23 | D20: =B20-C20 -> 1867.52 | E20: East | F20: Q1 | H20: Q3 | I20: South | J20: =SUMIFS($B$2:$B$129,$F$2:$F$129,H20,$E$2:$E$129,I20) -> 171876.91 | K20: =SUMIFS($D$2:$D$129,$F$2:$F$129,H20,$E$2:$E$129,I20) -> 56581.77
A21: Monitor | B21: 19494.23 | C21: 12944.54 | D21: =B21-C21 -> 6549.69 | E21: East | F21: Q1 | H21: Q3 | I21: East | J21: =SUMIFS($B$2:$B$129,$F$2:$F$129,H21,$E$2:$E$129,I21) -> 197248.68 | K21: =SUMIFS($D$2:$D$129,$F$2:$F$129,H21,$E$2:$E$129,I21) -> 58594.11
A22: Keyboard | B22: 2603.55 | C22: 1713.06 | D22: =B22-C22 -> 890.49 | E22: East | F22: Q1 | H22: Q3 | I22: West | J22: =SUMIFS($B$2:$B$129,$F$2:$F$129,H22,$E$2:$E$129,I22) -> 219902.77 | K22: =SUMIFS($D$2:$D$129,$F$2:$F$129,H22,$E$2:$E$129,I22) -> 67462.03
A23: Mouse | B23: 1359.59 | C23: 1108.9 | D23: =B23-C23 -> 250.69 | E23: East | F23: Q1 | H23: Q4 | I23: North | J23: =SUMIFS($B$2:$B$129,$F$2:$F$129,H23,$E$2:$E$129,I23) -> 232321.69 | K23: =SUMIFS($D$2:$D$129,$F$2:$F$129,H23,$E$2:$E$129,I23) -> 65562.6
A24: Tablet | B24: 26755.25 | C24: 21014.71 | D24: =B24-C24 -> 5740.54 | E24: East | F24: Q1 | H24: Q4 | I24: South | J24: =SUMIFS($B$2:$B$129,$F$2:$F$129,H24,$E$2:$E$129,I24) -> 228193.73 | K24: =SUMIFS($D$2:$D$129,$F$2:$F$129,H24,$E$2:$E$129,I24) -> 65575.08 | M24: Quarter | N24: North | O24: South | P24: East | Q24: West
A25: Printer | B25: 13223.18 | C25: 10285.57 | D25: =B25-C25 -> 2937.61 | E25: East | F25: Q1 | H25: Q4 | I25: East | J25: =SUMIFS($B$2:$B$129,$F$2:$F$129,H25,$E$2:$E$129,I25) -> 203115.31 | K25: =SUMIFS($D$2:$D$129,$F$2:$F$129,H25,$E$2:$E$129,I25) -> 48374.02 | M25: Q1 | N25: =SUMIFS($D$2:$D$129,$F$2:$F$129,$M25,$E$2:$E$129,N$24) -> 50009.1 | O25: =SUMIFS($D$2:$D$129,$F$2:$F$129,$M25,$E$2:$E$129,O$24) -> 48014.48 | P25: =SUMIFS($D$2:$D$129,$F$2:$F$129,$M25,$E$2:$E$129,P$24) -> 46040.26 | Q25: =SUMIFS($D$2:$D$129,$F$2:$F$129,$M25,$E$2:$E$129,Q$24) -> 50022.3
A26: Laptop | B26: 59827.04 | C26: 43048.84 | D26: =B26-C26 -> 16778.2 | E26: West | F26: Q1 | H26: Q4 | I26: West | J26: =SUMIFS($B$2:$B$129,$F$2:$F$129,H26,$E$2:$E$129,I26) -> 269768.8 | K26: =SUMIFS($D$2:$D$129,$F$2:$F$129,H26,$E$2:$E$129,I26) -> 70513.74 | M26: Q2 | N26: =SUMIFS($D$2:$D$129,$F$2:$F$129,$M26,$E$2:$E$129,N$24) -> 51658.6 | O26: =SUMIFS($D$2:$D$129,$F$2:$F$129,$M26,$E$2:$E$129,O$24) -> 47124.18 | P26: =SUMIFS($D$2:$D$129,$F$2:$F$129,$M26,$E$2:$E$129,P$24) -> 58962 | Q26: =SUMIFS($D$2:$D$129,$F$2:$F$129,$M26,$E$2:$E$129,Q$24) -> 51869.85
A27: Smartphone | B27: 47486.9 | C27: 31163.2 | D27: =B27-C27 -> 16323.7 | E27: West | F27: Q1 | M27: Q3 | N27: =SUMIFS($D$2:$D$129,$F$2:$F$129,$M27,$E$2:$E$129,N$24) -> 69564.59 | O27: =SUMIFS($D$2:$D$129,$F$2:$F$129,$M27,$E$2:$E$129,O$24) -> 56581.77 | P27: =SUMIFS($D$2:$D$129,$F$2:$F$129,$M27,$E$2:$E$129,P$24) -> 58594.11 | Q27: =SUMIFS($D$2:$D$129,$F$2:$F$129,$M27,$E$2:$E$129,Q$24) -> 67462.03
A28: Headphones | B28: 7671.72 | C28: 6245.84 | D28: =B28-C28 -> 1425.88 | E28: West | F28: Q1 | M28: Q4 | N28: =SUMIFS($D$2:$D$129,$F$2:$F$129,$M28,$E$2:$E$129,N$24) -> 65562.6 | O28: =SUMIFS($D$2:$D$129,$F$2:$F$129,$M28,$E$2:$E$129,O$24) -> 65575.08 | P28: =SUMIFS($D$2:$D$129,$F$2:$F$129,$M28,$E$2:$E$129,P$24) -> 48374.02 | Q28: =SUMIFS($D$2:$D$129,$F$2:$F$129,$M28,$E$2:$E$129,Q$24) -> 70513.74
A29: Monitor | B29: 16473.67 | C29: 11432.74 | D29: =B29-C29 -> 5040.93 | E29: West | F29: Q1
A30: Keyboard | B30: 2341.84 | C30: 1636.31 | D30: =B30-C30 -> 705.53 | E30: West | F30: Q1
A31: Mouse | B31: 1460.71 | C31: 1020.91 | D31: =B31-C31 -> 439.8 | E31: West | F31: Q1
A32: Tablet | B32: 18658.91 | C32: 11782.18 | D32: =B32-C32 -> 6876.73 | E32: West | F32: Q1
A33: Printer | B33: 15041.91 | C33: 12610.38 | D33: =B33-C33 -> 2431.53 | E33: West | F33: Q1
A34: Laptop | B34: 82970.02 | C34: 59991.81 | D34: =B34-C34 -> 22978.21 | E34: North | F34: Q2
A35: Smartphone | B35: 45983.55 | C35: 35962.84 | D35: =B35-C35 -> 10020.71 | E35: North | F35: Q2
A36: Headphones | B36: 5895.52 | C36: 4421.92 | D36: =B36-C36 -> 1473.6 | E36: North | F36: Q2
A37: Monitor | B37: 19769.59 | C37: 14890.52 | D37: =B37-C37 -> 4879.07 | E37: North | F37: Q2
A38: Keyboard | B38: 2208.37 | C38: 1433.5 | D38: =B38-C38 -> 774.87 | E38: North | F38: Q2
A39: Mouse | B39: 1175.01 | C39: 967.3 | D39: =B39-C39 -> 207.71 | E39: North | F39: Q2
A40: Tablet | B40: 25434.83 | C40: 19009.09 | D40: =B40-C40 -> 6425.74 | E40: North | F40: Q2
...

Sheet Summary
A1: PROFIT TRACKER — SALES SUMMARY
A2: Formula-based summary starter. For a true PivotTable and Quarter slicer, follow the steps in the project guide.
A4: Region | B4: Product | C4: Total Sales | D4: Total Expenses | E4: Total Profit | G4: PivotTable + Slicer checklist
A5: North | B5: Laptop | C5: =SUMIFS('Sales Data'!$B$2:$B$129,'Sales Data'!$E$2:$E$129,A5,'Sales Data'!$A$2:$A$129,B5) -> 314861.12 | D5: =SUMIFS('Sales Data'!$C$2:$C$129,'Sales Data'!$E$2:$E$129,A5,'Sales Data'!$A$2:$A$129,B5) -> 231762.59 | E5: =SUMIFS('Sales Data'!$D$2:$D$129,'Sales Data'!$E$2:$E$129,A5,'Sales Data'!$A$2:$A$129,B5) -> 83098.53 | G5: 1. Click inside SalesTable on Sales Data.
A6: North | B6: Smartphone | C6: =SUMIFS('Sales Data'!$B$2:$B$129,'Sales Data'!$E$2:$E$129,A6,'Sales Data'!$A$2:$A$129,B6) -> 214069.37 | D6: =SUMIFS('Sales Data'!$C$2:$C$129,'Sales Data'!$E$2:$E$129,A6,'Sales Data'!$A$2:$A$129,B6) -> 149097.63 | E6: =SUMIFS('Sales Data'!$D$2:$D$129,'Sales Data'!$E$2:$E$129,A6,'Sales Data'!$A$2:$A$129,B6) -> 64971.74 | G6: 2. Insert > PivotTable > From Table/Range.
A7: North | B7: Headphones | C7: =SUMIFS('Sales Data'!$B$2:$B$129,'Sales Data'!$E$2:$E$129,A7,'Sales Data'!$A$2:$A$129,B7) -> 27154.47 | D7: =SUMIFS('Sales Data'!$C$2:$C$129,'Sales Data'!$E$2:$E$129,A7,'Sales Data'!$A$2:$A$129,B7) -> 21922.74 | E7: =SUMIFS('Sales Data'!$D$2:$D$129,'Sales Data'!$E$2:$E$129,A7,'Sales Data'!$A$2:$A$129,B7) -> 5231.73 | G7: 3. Choose Existing Worksheet: Summary!G12 (or New Worksheet).
A8: North | B8: Monitor | C8: =SUMIFS('Sales Data'!$B$2:$B$129,'Sales Data'!$E$2:$E$129,A8,'Sales Data'!$A$2:$A$129,B8) -> 74243.61 | D8: =SUMIFS('Sales Data'!$C$2:$C$129,'Sales Data'!$E$2:$E$129,A8,'Sales Data'!$A$2:$A$129,B8) -> 52973.72 | E8: =SUMIFS('Sales Data'!$D$2:$D$129,'Sales Data'!$E$2:$E$129,A8,'Sales Data'!$A$2:$A$129,B8) -> 21269.89 | G8: 4. Rows: Region, then Product.
A9: North | B9: Keyboard | C9: =SUMIFS('Sales Data'!$B$2:$B$129,'Sales Data'!$E$2:$E$129,A9,'Sales Data'!$A$2:$A$129,B9) -> 10274.17 | D9: =SUMIFS('Sales Data'!$C$2:$C$129,'Sales Data'!$E$2:$E$129,A9,'Sales Data'!$A$2:$A$129,B9) -> 7563.98 | E9: =SUMIFS('Sales Data'!$D$2:$D$129,'Sales Data'!$E$2:$E$129,A9,'Sales Data'!$A$2:$A$129,B9) -> 2710.19 | G9: 5. Values: Sum of Sales, Sum of Expenses, Sum of Profit.
A10: North | B10: Mouse | C10: =SUMIFS('Sales Data'!$B$2:$B$129,'Sales Data'!$E$2:$E$129,A10,'Sales Data'!$A$2:$A$129,B10) -> 5260.48 | D10: =SUMIFS('Sales Data'!$C$2:$C$129,'Sales Data'!$E$2:$E$129,A10,'Sales Data'!$A$2:$A$129,B10) -> 3801.78 | E10: =SUMIFS('Sales Data'!$D$2:$D$129,'Sales Data'!$E$2:$E$129,A10,'Sales Data'!$A$2:$A$129,B10) -> 1458.7 | G10: 6. PivotTable Design > Subtotals > Show all subtotals.
A11: North | B11: Tablet | C11: =SUMIFS('Sales Data'!$B$2:$B$129,'Sales Data'!$E$2:$E$129,A11,'Sales Data'!$A$2:$A$129,B11) -> 116534.67 | D11: =SUMIFS('Sales Data'!$C$2:$C$129,'Sales Data'!$E$2:$E$129,A11,'Sales Data'!$A$2:$A$129,B11) -> 81434.76 | E11: =SUMIFS('Sales Data'!$D$2:$D$129,'Sales Data'!$E$2:$E$129,A11,'Sales Data'!$A$2:$A$129,B11) -> 35099.91 | G11: 7. Grand Totals > On for Rows and Columns.
A12: North | B12: Printer | C12: =SUMIFS('Sales Data'!$B$2:$B$129,'Sales Data'!$E$2:$E$129,A12,'Sales Data'!$A$2:$A$129,B12) -> 68515.92 | D12: =SUMIFS('Sales Data'!$C$2:$C$129,'Sales Data'!$E$2:$E$129,A12,'Sales Data'!$A$2:$A$129,B12) -> 45561.72 | E12: =SUMIFS('Sales Data'!$D$2:$D$129,'Sales Data'!$E$2:$E$129,A12,'Sales Data'!$A$2:$A$129,B12) -> 22954.2 | G12: 8. Sort Sum of Profit largest to smallest within each region.
A13: South | B13: Laptop | C13: =SUMIFS('Sales Data'!$B$2:$B$129,'Sales Data'!$E$2:$E$129,A13,'Sales Data'!$A$2:$A$129,B13) -> 290345.28 | D13: =SUMIFS('Sales Data'!$C$2:$C$129,'Sales Data'!$E$2:$E$129,A13,'Sales Data'!$A$2:$A$129,B13) -> 199476.94 | E13: =SUMIFS('Sales Data'!$D$2:$D$129,'Sales Data'!$E$2:$E$129,A13,'Sales Data'!$A$2:$A$129,B13) -> 90868.34 | G13: 9. PivotTable Analyze > Insert Slicer > Quarter > OK.
A14: South | B14: Smartphone | C14: =SUMIFS('Sales Data'!$B$2:$B$129,'Sales Data'!$E$2:$E$129,A14,'Sales Data'!$A$2:$A$129,B14) -> 184026.37 | D14: =SUMIFS('Sales Data'!$C$2:$C$129,'Sales Data'!$E$2:$E$129,A14,'Sales Data'!$A$2:$A$129,B14) -> 131186.44 | E14: =SUMIFS('Sales Data'!$D$2:$D$129,'Sales Data'!$E$2:$E$129,A14,'Sales Data'!$A$2:$A$129,B14) -> 52839.93 | G14: 10. Move slicer near the PivotTable and test Q1–Q4.
A15: South | B15: Headphones | C15: =SUMIFS('Sales Data'!$B$2:$B$129,'Sales Data'!$E$2:$E$129,A15,'Sales Data'!$A$2:$A$129,B15) -> 26650.14 | D15: =SUMIFS('Sales Data'!$C$2:$C$129,'Sales Data'!$E$2:$E$129,A15,'Sales Data'!$A$2:$A$129,B15) -> 20210.8 | E15: =SUMIFS('Sales Data'!$D$2:$D$129,'Sales Data'!$E$2:$E$129,A15,'Sales Data'!$A$2:$A$129,B15) -> 6439.34 | G15: 11. To refresh after edits: right-click PivotTable > Refresh.
A16: South | B16: Monitor | C16: =SUMIFS('Sales Data'!$B$2:$B$129,'Sales Data'!$E$2:$E$129,A16,'Sales Data'!$A$2:$A$129,B16) -> 76168.09 | D16: =SUMIFS('Sales Data'!$C$2:$C$129,'Sales Data'!$E$2:$E$129,A16,'Sales Data'!$A$2:$A$129,B16) -> 56141.04 | E16: =SUMIFS('Sales Data'!$D$2:$D$129,'Sales Data'!$E$2:$E$129,A16,'Sales Data'!$A$2:$A$129,B16) -> 20027.05
A17: South | B17: Keyboard | C17: =SUMIFS('Sales Data'!$B$2:$B$129,'Sales Data'!$E$2:$E$129,A17,'Sales Data'!$A$2:$A$129,B17) -> 11272.47 | D17: =SUMIFS('Sales Data'!$C$2:$C$129,'Sales Data'!$E$2:$E$129,A17,'Sales Data'!$A$2:$A$129,B17) -> 8312.5 | E17: =SUMIFS('Sales Data'!$D$2:$D$129,'Sales Data'!$E$2:$E$129,A17,'Sales Data'!$A$2:$A$129,B17) -> 2959.97
A18: South | B18: Mouse | C18: =SUMIFS('Sales Data'!$B$2:$B$129,'Sales Data'!$E$2:$E$129,A18,'Sales Data'!$A$2:$A$129,B18) -> 5729.76 | D18: =SUMIFS('Sales Data'!$C$2:$C$129,'Sales Data'!$E$2:$E$129,A18,'Sales Data'!$A$2:$A$129,B18) -> 3969.27 | E18: =SUMIFS('Sales Data'!$D$2:$D$129,'Sales Data'!$E$2:$E$129,A18,'Sales Data'!$A$2:$A$129,B18) -> 1760.49
A19: South | B19: Tablet | C19: =SUMIFS('Sales Data'!$B$2:$B$129,'Sales Data'!$E$2:$E$129,A19,'Sales Data'!$A$2:$A$129,B19) -> 106244.81 | D19: =SUMIFS('Sales Data'!$C$2:$C$129,'Sales Data'!$E$2:$E$129,A19,'Sales Data'!$A$2:$A$129,B19) -> 76609.06 | E19: =SUMIFS('Sales Data'!$D$2:$D$129,'Sales Data'!$E$2:$E$129,A19,'Sales Data'!$A$2:$A$129,B19) -> 29635.75
A20: South | B20: Printer | C20: =SUMIFS('Sales Data'!$B$2:$B$129,'Sales Data'!$E$2:$E$129,A20,'Sales Data'!$A$2:$A$129,B20) -> 57163.66 | D20: =SUMIFS('Sales Data'!$C$2:$C$129,'Sales Data'!$E$2:$E$129,A20,'Sales Data'!$A$2:$A$129,B20) -> 44399.02 | E20: =SUMIFS('Sales Data'!$D$2:$D$129,'Sales Data'!$E$2:$E$129,A20,'Sales Data'!$A$2:$A$129,B20) -> 12764.64
A21: East | B21: Laptop | C21: =SUMIFS('Sales Data'!$B$2:$B$129,'Sales Data'!$E$2:$E$129,A21,'Sales Data'!$A$2:$A$129,B21) -> 319003.11 | D21: =SUMIFS('Sales Data'!$C$2:$C$129,'Sales Data'!$E$2:$E$129,A21,'Sales Data'!$A$2:$A$129,B21) -> 215711.55 | E21: =SUMIFS('Sales Data'!$D$2:$D$129,'Sales Data'!$E$2:$E$129,A21,'Sales Data'!$A$2:$A$129,B21) -> 103291.56
A22: East | B22: Smartphone | C22: =SUMIFS('Sales Data'!$B$2:$B$129,'Sales Data'!$E$2:$E$129,A22,'Sales Data'!$A$2:$A$129,B22) -> 166479.99 | D22: =SUMIFS('Sales Data'!$C$2:$C$129,'Sales Data'!$E$2:$E$129,A22,'Sales Data'!$A$2:$A$129,B22) -> 129586.66 | E22: =SUMIFS('Sales Data'!$D$2:$D$129,'Sales Data'!$E$2:$E$129,A22,'Sales Data'!$A$2:$A$129,B22) -> 36893.33
A23: East | B23: Headphones | C23: =SUMIFS('Sales Data'!$B$2:$B$129,'Sales Data'!$E$2:$E$129,A23,'Sales Data'!$A$2:$A$129,B23) -> 29594.13 | D23: =SUMIFS('Sales Data'!$C$2:$C$129,'Sales Data'!$E$2:$E$129,A23,'Sales Data'!$A$2:$A$129,B23) -> 22042.79 | E23: =SUMIFS('Sales Data'!$D$2:$D$129,'Sales Data'!$E$2:$E$129,A23,'Sales Data'!$A$2:$A$129,B23) -> 7551.34
A24: East | B24: Monitor | C24: =SUMIFS('Sales Data'!$B$2:$B$129,'Sales Data'!$E$2:$E$129,A24,'Sales Data'!$A$2:$A$129,B24) -> 77565.13 | D24: =SUMIFS('Sales Data'!$C$2:$C$129,'Sales Data'!$E$2:$E$129,A24,'Sales Data'!$A$2:$A$129,B24) -> 54147.06 | E24: =SUMIFS('Sales Data'!$D$2:$D$129,'Sales Data'!$E$2:$E$129,A24,'Sales Data'!$A$2:$A$129,B24) -> 23418.07
A25: East | B25: Keyboard | C25: =SUMIFS('Sales Data'!$B$2:$B$129,'Sales Data'!$E$2:$E$129,A25,'Sales Data'!$A$2:$A$129,B25) -> 10050.38 | D25: =SUMIFS('Sales Data'!$C$2:$C$129,'Sales Data'!$E$2:$E$129,A25,'Sales Data'!$A$2:$A$129,B25) -> 7402.14 | E25: =SUMIFS('Sales Data'!$D$2:$D$129,'Sales Data'!$E$2:$E$129,A25,'Sales Data'!$A$2:$A$129,B25) -> 2648.24
A26: East | B26: Mouse | C26: =SUMIFS('Sales Data'!$B$2:$B$129,'Sales Data'!$E$2:$E$129,A26,'Sales Data'!$A$2:$A$129,B26) -> 5136.91 | D26: =SUMIFS('Sales Data'!$C$2:$C$129,'Sales Data'!$E$2:$E$129,A26,'Sales Data'!$A$2:$A$129,B26) -> 3880.19 | E26: =SUMIFS('Sales Data'!$D$2:$D$129,'Sales Data'!$E$2:$E$129,A26,'Sales Data'!$A$2:$A$129,B26) -> 1256.72
A27: East | B27: Tablet | C27: =SUMIFS('Sales Data'!$B$2:$B$129,'Sales Data'!$E$2:$E$129,A27,'Sales Data'!$A$2:$A$129,B27) -> 97342.75 | D27: =SUMIFS('Sales Data'!$C$2:$C$129,'Sales Data'!$E$2:$E$129,A27,'Sales Data'!$A$2:$A$129,B27) -> 75124.95 | E27: =SUMIFS('Sales Data'!$D$2:$D$129,'Sales Data'!$E$2:$E$129,A27,'Sales Data'!$A$2:$A$129,B27) -> 22217.8
... A36: West | B36: Printer | C36: =SUMIFS('Sales Data'!$B$2:$B$129,'Sales Data'!$E$2:$E$129,A36,'Sales Data'!$A$2:$A$129,B36) -> 62552.46 | D36: =SUMIFS('Sales Data'!$C$2:$C$129,'Sales Data'!$E$2:$E$129,A36,'Sales Data'!$A$2:$A$129,B36) -> 47990.71 | E36: =SUMIFS('Sales Data'!$D$2:$D$129,'Sales Data'!$E$2:$E$129,A36,'Sales Data'!$A$2:$A$129,B36) -> 14561.75

Sheet Read Me
A1: Profit Tracker — Project Guide
A3: 1. Dataset | B3: Sales Data contains 128 sample records: 8 products × 4 regions × 4 quarters. Sales and Expenses are sample INR values; Profit is calculated with a formula.
A4: 2. Formulas | B4: Quarterly metrics are already set up in columns H:K using AVERAGEIF, SUMIFS, and MAXIFS. Change source values to see results recalculate in Excel.
A5: 3. Charts | B5: Two line charts are included: quarterly Sales by Region and quarterly Profit by Region. The charts are formula-linked to the dataset.
A6: 4. Conditional formatting | B6: Sales above ₹80,000 are highlighted green; Profit below ₹5,000 is highlighted red. Profit also uses a color scale.
A7: 5. Sales validation | B7: Sales accepts positive numeric values only and shows an input message/error alert.
A8: 6. Product uniqueness note | B8: The project brief's unique-product validation conflicts with the analysis dataset: the same product must appear in multiple regions/quarters for a meaningful PivotTable. Sample rows intentionally repeat product names. The validation rule is included for new entries, but Excel does not retroactively remove existing repeats. For real sales data, a product dropdown from a master list is usually better.
A9: 7. Create true PivotTable | B9: On Sales Data, click any cell in SalesTable > Insert > PivotTable. Put it on Summary at G12 or choose New Worksheet. Add Region and Product to Rows; Sales, Expenses, Profit to Values as Sum.
A10: 8. Subtotals & grand totals | B10: In PivotTable Design, enable subtotals and grand totals for rows and columns.
A11: 9. Highlight top product | B11: Sort Sum of Profit descending within each Region, or apply Home > Conditional Formatting > Top/Bottom Rules to the profit values. For a per-region top product, use a region-by-region sort/inspection or a separate formula ranking.
A12: 10. Quarter slicer | B12: Select PivotTable > PivotTable Analyze > Insert Slicer > check Quarter > OK. Drag the slicer near the PivotTable and test each quarter.
A13: 11. Save | B13: Save as .xlsx. Keep the original sample workbook as a backup before replacing or deleting data.

Sheet Charts
A3: Sum of Sales | B3: Column Labels
A4: Row Labels | B4: East | C4: North | D4: South | E4: West | F4: Grand Total
A5: Q1 | B5: 171984.49 | C5: 178772.34 | D5: 167559.26 | E5: 168962.7 | F5: 687278.79
A6: Q2 | B6: 191941.91 | C6: 196812.25 | D6: 189970.68 | E6: 199409.58 | F6: 778134.42
A7: Q3 | B7: 197248.68 | C7: 223007.53 | D7: 171876.91 | E7: 219902.77 | F7: 812035.89
A8: Q4 | B8: 203115.31 | C8: 232321.69 | D8: 228193.73 | E8: 269768.8 | F8: 933399.53
A9: Grand Total | B9: 764290.39 | C9: 830913.81 | D9: 757600.58 | E9: 858043.85 | F9: 3210848.6
A29: Sum of Profit | B29: Column Labels
A30: Row Labels | B30: East | C30: North | D30: South | E30: West | F30: Grand Total
A31: Q1 | B31: 46040.26 | C31: 50009.1 | D31: 48014.48 | E31: 50022.3 | F31: 194086.14
A32: Q2 | B32: 58962 | C32: 51658.6 | D32: 47124.18 | E32: 51869.85 | F32: 209614.63
A33: Q3 | B33: 58594.11 | C33: 69564.59 | D33: 56581.77 | E33: 67462.03 | F33: 252202.5
A34: Q4 | B34: 48374.02 | C34: 65562.6 | D34: 65575.08 | E34: 70513.74 | F34: 250025.44
A35: Grand Total | B35: 211970.39 | C35: 236794.89 | D35: 217295.51 | E35: 239867.92 | F35: 905928.71
A39: Quarter | B39: (All)
A41: Row Labels | B41: Sum of Sales | C41: Sum of Profit | D41: Sum of Expenses
A42: East | B42: 764290.39 | C42: 211970.39 | D42: 552320
A43: Headphones | B43: 29594.13 | C43: 7551.34 | D43: 22042.79
A44: Keyboard | B44: 10050.38 | C44: 2648.24 | D44: 7402.14
A45: Laptop | B45: 319003.11 | C45: 103291.56 | D45: 215711.55
A46: Monitor | B46: 77565.13 | C46: 23418.07 | D46: 54147.06
A47: Mouse | B47: 5136.91 | C47: 1256.72 | D47: 3880.19
A48: Printer | B48: 59117.99 | C48: 14693.33 | D48: 44424.66
A49: Smartphone | B49: 166479.99 | C49: 36893.33 | D49: 129586.66
A50: Tablet | B50: 97342.75 | C50: 22217.8 | D50: 75124.95
A51: North | B51: 830913.81 | C51: 236794.89 | D51: 594118.92
A52: Headphones | B52: 27154.47 | C52: 5231.73 | D52: 21922.74
A53: Keyboard | B53: 10274.17 | C53: 2710.19 | D53: 7563.98
... A78: Grand Total | B78: 3210848.6 | C78: 905928.71 | D78: 2304919.9

Sheet DASHBOARD
H1: SALES ANALYSIS DASHBOARD
